<?xml version="1.0" ?>
<!-- =================================================================================== -->
<!-- |    This document was autogenerated by xacro from urdf/akros2_mecanum/robot.urdf.xacro | -->
<!-- |    EDITING THIS FILE BY HAND IS NOT RECOMMENDED                                 | -->
<!-- =================================================================================== -->
<robot name="akros2_mecanum">
  <!-- All values below are based on the CAD model (Fusion 360). 2mm added on each side (4mm total) for length and width (but not height) as padding. -->
  <!-- colors from https://gist.github.com/naoki-mizuno/5e63a13597d5c5fe817c1600b829595e -->
  <material name="SensorColor">
    <color rgba="0.027450980392156862 0.050980392156862744 0.050980392156862744 1.0" /> <!-- almostblack -->
  </material>
  <material name="WheelsNavColor">
     <color rgba="0.21176470588235294 0.21568627450980393 0.21568627450980393 1.0" /> <!-- darkgrey -->
  </material>
  <material name="BaseLinkColor">
    <color rgba="0.5725490196078431 0.5843137254901961 0.5686274509803921 1.0" /> <!-- grey -->
  </material>
  <!-- WHEEL_LF TRANSMISSION -->
  <transmission name="trans_lf">
    <type>transmission_interface/SimpleTransmission</type>
    <joint name="joint_lf">
      <hardwareInterface>hardware_interface/VelocityJointInterface</hardwareInterface>
    </joint>
    <actuator name="motor_lf">
      <hardwareInterface>hardware_interface/VelocityJointInterface</hardwareInterface>
      <mechanicalReduction>1</mechanicalReduction>
    </actuator>
  </transmission>
  <!-- WHEEL_LB TRANSMISSION -->
  <transmission name="trans_lb">
    <type>transmission_interface/SimpleTransmission</type>
    <joint name="joint_lb">
      <hardwareInterface>hardware_interface/VelocityJointInterface</hardwareInterface>
    </joint>
    <actuator name="motor_lb">
      <hardwareInterface>hardware_interface/VelocityJointInterface</hardwareInterface>
      <mechanicalReduction>1</mechanicalReduction>
    </actuator>
  </transmission>
  <!-- WHEEL_RF TRANSMISSION -->
  <transmission name="trans_rf">
    <type>transmission_interface/SimpleTransmission</type>
    <joint name="joint_rf">
      <hardwareInterface>hardware_interface/VelocityJointInterface</hardwareInterface>
    </joint>
    <actuator name="motor_rf">
      <hardwareInterface>hardware_interface/VelocityJointInterface</hardwareInterface>
      <mechanicalReduction>1</mechanicalReduction>
    </actuator>
  </transmission>
  <!-- WHEEL_RB TRANSMISSION -->
  <transmission name="trans_rb">
    <type>transmission_interface/SimpleTransmission</type>
    <joint name="joint_rb">
      <hardwareInterface>hardware_interface/VelocityJointInterface</hardwareInterface>
    </joint>
    <actuator name="motor_rb">
      <hardwareInterface>hardware_interface/VelocityJointInterface</hardwareInterface>
      <mechanicalReduction>1</mechanicalReduction>
    </actuator>
  </transmission>
  <gazebo reference="base_link">
    <material>Gazebo/Grey</material>
  </gazebo>
  <gazebo reference="nav_link">
    <material>Gazebo/DarkGrey</material>
  </gazebo>
  <gazebo reference="laser_link">
    <material>Gazebo/FlatBlack</material>
  </gazebo>
  <gazebo reference="cam_link">
    <material>Gazebo/FlatBlack</material>
  </gazebo>
  <gazebo reference="wheel_lf">
    <material>Gazebo/DarkGrey</material>
  </gazebo>
  <gazebo reference="wheel_lb">
    <material>Gazebo/DarkGrey</material>
  </gazebo>
  <gazebo reference="wheel_rf">
    <material>Gazebo/DarkGrey</material>
  </gazebo>
  <gazebo reference="wheel_rb">
    <material>Gazebo/DarkGrey</material>
  </gazebo>
  <gazebo reference="laser_frame">
    <sensor name="laser" type="ray">
      <pose>0 0 0 0 0 0</pose>
      <visualize>true</visualize>
      <update_rate>10</update_rate>
      <ray>
        <scan>
          <horizontal>
            <samples>360</samples>
            <min_angle>-3.14159265</min_angle>
            <max_angle>3.14159265</max_angle>
          </horizontal>
        </scan>
        <range>
          <min>0.02</min>
          <max>12.0</max>
          <resolution>0.01</resolution>
        </range>
        <noise>
          <type>gaussian</type>
          <mean>0.0</mean>
          <stddev>0.01</stddev>
        </noise>
      </ray>
      <plugin filename="libgazebo_ros_laser.so" name="gazebo_laser_controller">
        <topicName>scan</topicName>
        <frameName>laser_frame</frameName>
      </plugin>
    </sensor>
  </gazebo>
  <gazebo reference="cam_link">
    <sensor name="camera" type="camera">
      <pose> 0 0 0 0 0 0 </pose>
      <visualize>true</visualize>
      <update_rate>10</update_rate>
      <camera>
        <horizontal_fov>1.0472</horizontal_fov>
        <image>
          <format>R8G8B8</format>
          <width>640</width>
          <height>480</height>
        </image>
        <clip>
          <near>0.05</near>
          <far>8.0</far>
        </clip>
      </camera>
      <plugin filename="libgazebo_ros_camera.so" name="gazebo_cam_controller">
        <frame_name>cam_frame</frame_name>
      </plugin>
    </sensor>
  </gazebo>
  <gazebo>
    <plugin filename="libgazebo_ros_imu.so" name="imu_plugin">
      <alwaysOn>true</alwaysOn>
      <bodyName>imu_link</bodyName>
      <frameName>imu_link</frameName>
      <topicName>imu</topicName>
      <serviceName>imu_service</serviceName>
      <gaussianNoise>0.0</gaussianNoise>
      <updateRate>200</updateRate>
      <imu>
        <noise>
          <type>gaussian</type>
          <rate>
            <mean>0.0</mean>
            <stddev>2e-4</stddev>
            <bias_mean>0.0000075</bias_mean>
            <bias_stddev>0.0000008</bias_stddev>
          </rate>
          <accel>
            <mean>0.0</mean>
            <stddev>1.7e-2</stddev>
            <bias_mean>0.1</bias_mean>
            <bias_stddev>0.001</bias_stddev>
          </accel>
        </noise>
      </imu>
    </plugin>
  </gazebo>
  <gazebo>
    <plugin filename="libgazebo_ros_planar_move.so" name="omni_steering">
      <commandTopic>cmd_vel</commandTopic>
      <odometryTopic>odom</odometryTopic>
      <odometryFrame>odom</odometryFrame>
      <odometryRate>100.0</odometryRate>
      <robotBaseFrame>base_link</robotBaseFrame>
      <publishTF>false</publishTF>
    </plugin>
  </gazebo>
  <!--<gazebo>
  <plugin name="control" filename="libgazebo_ros_control.so"/>
</gazebo>-->
  <!-- **** LINKS **** -->
  <!-- BASE_LINK -->
  <link name="base_link">
    <visual>
      <origin rpy="0 0 0" xyz="0 0 0"/>
      <geometry>
        <mesh filename="base_module.stl"/>
      </geometry>
      <material name="BaseLinkColor"/>
    </visual>
    <collision>
      <origin rpy="0 0 0" xyz="0.003 0 0.0495"/>
      <geometry>
        <box size="0.21038 0.1585 0.099"/>
      </geometry>
    </collision>
  </link>
  <!-- BASE_LINK_INERTIAL (WORKAROUND FOR KDL WHICH DOES NOT ACCEPT BASE_LINK WITH INERTIA) -->
  <link name="base_link_inertial">
    <inertial>
      <origin rpy="0 0 0" xyz="0 0 0"/>
      <mass value="2.0"/>
      <inertia ixx="0.0058205416666666674" ixy="0" ixz="0" iyy="0.009010124066666667" iyz="0" izz="0.009010124066666667"/>
    </inertial>
  </link>
  <!-- BASE_FOOTPRINT -->
  <link name="base_footprint"/>
  <!-- NAV_LINK -->
  <link name="nav_link">
    <inertial>
      <mass value="0.5"/>
      <inertia ixx="0.0010859030208333334" ixy="0" ixz="0" iyy="0.0017799492708333335" iyz="0" izz="0.0017799492708333335"/>
    </inertial>
    <visual>
      <origin rpy="0 0 0" xyz="0 0 -0.099"/>
      <geometry>
        <mesh filename="navigation_module.stl"/>
      </geometry>
      <material name="WheelsNavColor"/>
    </visual>
    <collision>
      <origin rpy="0 0 0" xyz="0 0 0.015325"/>
      <geometry>
        <box size="0.2044 0.1585 0.03065"/>
      </geometry>
    </collision>
  </link>
  <!-- LD06 LASER_LINK -->
  <link name="laser_link">
    <inertial>
      <origin rpy="0 0 0" xyz="0 0 0"/>
      <mass value="0.12"/>
      <inertia ixx="2.86141e-05" ixy="0" ixz="0" iyy="2.8530000000000003e-05" iyz="0" izz="2.8530000000000003e-05"/>
    </inertial>
    <visual>
      <origin rpy="0 0 -1.5707963" xyz="0 0 0"/>
      <geometry>
        <mesh filename="ld06.stl"/>
      </geometry>
      <material name="SensorColor"/>
    </visual>
    <collision>
      <origin rpy="0 0 -1.5707963" xyz="0 0 0.0165"/>
      <geometry>
        <box size="0.042 0.0421 0.033"/>
      </geometry>
    </collision>
  </link>
  <!-- LASER_FRAME -->
  <link name="laser_frame"/>
  <!-- USB CAMERA MODULE CAM_LINK -->
  <link name="cam_link">
    <inertial>
      <origin rpy="0 0 0" xyz="0 0 0"/>
      <mass value="0.025"/>
      <inertia ixx="1.1310416666666668e-05" ixy="0" ixz="0" iyy="7.483541666666668e-07" iyz="0" izz="7.483541666666668e-07"/>
    </inertial>
    <visual>
      <origin rpy="0 0 0" xyz="0 0 0"/>
      <geometry>
        <mesh filename="cam_module.stl"/>
      </geometry>
      <material name="SensorColor"/>
    </visual>
    <collision>
      <origin rpy="0 0 0" xyz="0.00805 0 0"/>
      <geometry>
        <box size="0.0161 0.0421 0.033"/>
      </geometry>
    </collision>
  </link>
  <!-- USB CAMERA OPTICAL FRAME CAM_FRAME -->
  <link name="cam_frame"/>
  <!-- MPU9250 IMU_LINK -->
  <link name="imu_link"/>
  <!-- WHEEL LEFT FRONT -->
  <link name="wheel_lf">
    <inertial>
      <mass value="0.075"/>
      <inertia ixx="3.5017187499999997e-05" ixy="0" ixz="0" iyy="3.5017187499999997e-05" iyz="0" izz="5.5584374999999994e-05"/>
    </inertial>
    <visual>
      <origin rpy="0 0 0" xyz="0 0 0"/>
      <geometry>
        <mesh filename="wheel_lf.stl"/>
      </geometry>
      <material name="WheelsNavColor"/>
    </visual>
    <collision>
      <origin rpy="1.5707963 0 0" xyz="0 0.017 0"/>
      <geometry>
        <cylinder length="0.034" radius="0.0385"/>
      </geometry>
    </collision>
  </link>
  <!-- WHEEL LEFT BACK -->
  <link name="wheel_lb">
    <inertial>
      <mass value="0.075"/>
      <inertia ixx="3.5017187499999997e-05" ixy="0" ixz="0" iyy="3.5017187499999997e-05" iyz="0" izz="5.5584374999999994e-05"/>
    </inertial>
    <visual>
      <origin rpy="0 0 0" xyz="0 0 0"/>
      <geometry>
        <mesh filename="wheel_lb.stl"/>
      </geometry>
      <material name="WheelsNavColor"/>
    </visual>
    <collision>
      <origin rpy="1.5707963 0 0" xyz="0 0.017 0"/>
      <geometry>
        <cylinder length="0.034" radius="0.0385"/>
      </geometry>
    </collision>
  </link>
  <!-- WHEEL RIGHT FRONT -->
  <link name="wheel_rf">
    <inertial>
      <mass value="0.075"/>
      <inertia ixx="3.5017187499999997e-05" ixy="0" ixz="0" iyy="3.5017187499999997e-05" iyz="0" izz="5.5584374999999994e-05"/>
    </inertial>
    <visual>
      <origin rpy="0 0 0" xyz="0 0 0"/>
      <geometry>
        <mesh filename="wheel_rf.stl"/>
      </geometry>
      <material name="WheelsNavColor"/>
    </visual>
    <collision>
      <origin rpy="1.5707963 0 0" xyz="0 -0.017 0"/>
      <geometry>
        <cylinder length="0.034" radius="0.0385"/>
      </geometry>
    </collision>
  </link>
  <!-- WHEEL RIGHT BACK -->
  <link name="wheel_rb">
    <inertial>
      <mass value="0.075"/>
      <inertia ixx="3.5017187499999997e-05" ixy="0" ixz="0" iyy="3.5017187499999997e-05" iyz="0" izz="5.5584374999999994e-05"/>
    </inertial>
    <visual>
      <origin rpy="0 0 0" xyz="0 0 0"/>
      <geometry>
        <mesh filename="wheel_rb.stl"/>
      </geometry>
      <material name="WheelsNavColor"/>
    </visual>
    <collision>
      <origin rpy="1.5707963 0 0" xyz="0 -0.017 0"/>
      <geometry>
        <cylinder length="0.034" radius="0.0385"/>
      </geometry>
    </collision>
  </link>
  <!-- **** JOINTS **** -->
  <!-- BASE_LINK_INERTIAL TO BASE_LINK -->
  <joint name="base_inertial_fixed" type="fixed">
    <parent link="base_link"/>
    <child link="base_link_inertial"/>
    <origin xyz="0 0 0"/>
  </joint>
  <!-- BASE_FOOTPRINT TO BASE_LINK -->
  <joint name="base_footprint_fixed" type="fixed">
    <parent link="base_link"/>
    <child link="base_footprint"/>
    <origin xyz="0 0 -0.017877"/>
  </joint>
  <!-- NAV_LINK TO BASE_LINK -->
  <joint name="base_nav_fixed" type="fixed">
    <parent link="base_link"/>
    <child link="nav_link"/>
    <origin xyz="0 0 0.099"/>
    <axis xyz="0 0 0"/>
  </joint>
  <!-- LASER_LINK TO NAV_LINK -->
  <joint name="nav_laser_fixed" type="fixed">
    <parent link="nav_link"/>
    <child link="laser_link"/>
    <origin xyz="0.0632 0 0.015325"/>
  </joint>
  <!-- LASER_FRAME TO LASER_LINK -->
  <joint name="laser_frame_fixed" type="fixed">
    <parent link="laser_link"/>
    <child link="laser_frame"/>
    <origin xyz="0 0 0.0255"/>
  </joint>
  <!-- CAM_LINK TO NAV_LINK -->
  <joint name="nav_cam_fixed" type="fixed">
    <parent link="nav_link"/>
    <child link="cam_link"/>
    <origin xyz="0.0877 0 0.01525"/>
  </joint>
  <!-- CAM_FRAME TO CAM_LINK -->
  <joint name="cam_frame_fixed" type="fixed">
    <parent link="cam_link"/>
    <child link="cam_frame"/>
    <origin rpy="-1.5707963 0 -1.5707963" xyz="0.0065 0 0"/>
  </joint>
  <!-- IMU_LINK TO BASE_LINK -->
  <joint name="imu_base_fixed" type="fixed">
    <parent link="base_link"/>
    <child link="imu_link"/>
    <origin xyz="0.0562 0 0.094"/>
  </joint>
  <!-- WHEEL_LF TO BASE_LINK -->
  <joint name="joint_lf" type="continuous">
    <parent link="base_link"/>
    <child link="wheel_lf"/>
    <origin rpy="0 0 0" xyz="0.0495 0.0854225 0.021"/>
    <axis xyz="0 1 0"/>
  </joint>
  <!-- WHEEL_LB TO BASE_LINK -->
  <joint name="joint_lb" type="continuous">
    <parent link="base_link"/>
    <child link="wheel_lb"/>
    <origin rpy="0 0 0" xyz="-0.0495 0.0854225 0.021"/>
    <axis xyz="0 1 0"/>
  </joint>
  <!-- WHEEL_RF TO BASE_LINK -->
  <joint name="joint_rf" type="continuous">
    <parent link="base_link"/>
    <child link="wheel_rf"/>
    <origin rpy="0 0 0" xyz="0.0495 -0.0854225 0.021"/>
    <axis xyz="0 1 0"/>
  </joint>
  <!-- WHEEL_RB TO BASE_LINK -->
  <joint name="joint_rb" type="continuous">
    <parent link="base_link"/>
    <child link="wheel_rb"/>
    <origin rpy="0 0 0" xyz="-0.0495 -0.0854225 0.021"/>
    <axis xyz="0 1 0"/>
  </joint>
</robot>
