<?xml version="1.0" ?>
<!-- =================================================================================== -->
<!-- |    This document was autogenerated by xacro from urdf/akros2_omni/robot.urdf.xacro | -->
<!-- |    EDITING THIS FILE BY HAND IS NOT RECOMMENDED                                 | -->
<!-- =================================================================================== -->
<robot name="akros2_omni">
  <!-- All values below are based on the CAD model (Fusion 360) -->
  <!-- color codes from https://gist.github.com/naoki-mizuno/5e63a13597d5c5fe817c1600b829595e -->
  <material name="LaserColor">
     <color rgba="0.027450980392156862 0.050980392156862744 0.050980392156862744 1.0" /> <!-- almost black -->
  </material>
  <material name="WheelsNavColor">
    <color rgba="0.21176470588235294 0.21568627450980393 0.21568627450980393 1.0" /> <!-- darkgrey -->
  </material>
  <material name="BaseLinkColor">
     <color rgba="0.5725490196078431 0.5843137254901961 0.5686274509803921 1.0" /> <!-- grey -->
  </material>
  <!-- WHEEL_F TRANSMISSION -->
  <transmission name="trans_f">
    <type>transmission_interface/SimpleTransmission</type>
    <joint name="joint_f">
      <hardwareInterface>hardware_interface/VelocityJointInterface</hardwareInterface>
    </joint>
    <actuator name="motor_f">
      <hardwareInterface>hardware_interface/VelocityJointInterface</hardwareInterface>
      <mechanicalReduction>1</mechanicalReduction>
    </actuator>
  </transmission>
  <!-- WHEEL_L TRANSMISSION -->
  <transmission name="trans_l">
    <type>transmission_interface/SimpleTransmission</type>
    <joint name="joint_l">
      <hardwareInterface>hardware_interface/VelocityJointInterface</hardwareInterface>
    </joint>
    <actuator name="motor_l">
      <hardwareInterface>hardware_interface/VelocityJointInterface</hardwareInterface>
      <mechanicalReduction>1</mechanicalReduction>
    </actuator>
  </transmission>
  <!-- WHEEL_R TRANSMISSION -->
  <transmission name="trans_r">
    <type>transmission_interface/SimpleTransmission</type>
    <joint name="joint_r">
      <hardwareInterface>hardware_interface/VelocityJointInterface</hardwareInterface>
    </joint>
    <actuator name="motor_r">
      <hardwareInterface>hardware_interface/VelocityJointInterface</hardwareInterface>
      <mechanicalReduction>1</mechanicalReduction>
    </actuator>
  </transmission>
  <gazebo reference="base_link">
    <material>Gazebo/Grey</material>
  </gazebo>
  <gazebo reference="laser_link">
    <material>Gazebo/FlatBlack</material>
  </gazebo>
  <gazebo reference="wheel_f">
    <material>Gazebo/DarkGrey</material>
  </gazebo>
  <gazebo reference="wheel_l">
    <material>Gazebo/DarkGrey</material>
  </gazebo>
  <gazebo reference="wheel_r">
    <material>Gazebo/DarkGrey</material>
  </gazebo>
  <gazebo reference="laser_frame">
    <sensor name="head_ld06_sensor" type="ray">
      <pose>0 0 0.06 0 0 0</pose>
      <visualize>false</visualize>
      <update_rate>40</update_rate>
      <ray>
        <scan>
          <horizontal>
            <samples>720</samples>
            <resolution>1</resolution>
            <min_angle>-3.14159265</min_angle>
            <max_angle>3.14159265</max_angle>
          </horizontal>
        </scan>
        <range>
          <min>0.2</min>
          <max>30.0</max>
          <resolution>0.01</resolution>
        </range>
        <noise>
          <type>gaussian</type>
          <mean>0.0</mean>
          <stddev>0.01</stddev>
        </noise>
      </ray>
      <plugin filename="libgazebo_ros_laser.so" name="gazebo_ros_head_ld06_controller">
        <topicName>scan</topicName>
        <frameName>laser_frame</frameName>
      </plugin>
    </sensor>
  </gazebo>
  <gazebo>
    <plugin filename="libgazebo_ros_imu.so" name="imu_plugin">
      <alwaysOn>true</alwaysOn>
      <bodyName>imu_link</bodyName>
      <frameName>imu_link</frameName>
      <topicName>imu</topicName>
      <serviceName>imu_service</serviceName>
      <gaussianNoise>0.0</gaussianNoise>
      <updateRate>200</updateRate>
      <imu>
        <noise>
          <type>gaussian</type>
          <rate>
            <mean>0.0</mean>
            <stddev>2e-4</stddev>
            <bias_mean>0.0000075</bias_mean>
            <bias_stddev>0.0000008</bias_stddev>
          </rate>
          <accel>
            <mean>0.0</mean>
            <stddev>1.7e-2</stddev>
            <bias_mean>0.1</bias_mean>
            <bias_stddev>0.001</bias_stddev>
          </accel>
        </noise>
      </imu>
    </plugin>
  </gazebo>
  <gazebo>
    <plugin filename="libgazebo_ros_planar_move.so" name="omni_steering">
      <commandTopic>cmd_vel</commandTopic>
      <odometryTopic>odom</odometryTopic>
      <odometryFrame>odom</odometryFrame>
      <odometryRate>100.0</odometryRate>
      <robotBaseFrame>base_link</robotBaseFrame>
      <publishTF>false</publishTF>
    </plugin>
  </gazebo>
  <!--<gazebo>
  <plugin name="control" filename="libgazebo_ros_control.so"/>
</gazebo>-->
  <!-- **** LINKS **** -->
  <!-- BASE_LINK -->
  <link name="base_link">
    <visual>
      <origin rpy="0 0 0" xyz="0 0 0"/>
      <geometry>
        <mesh filename="base_module.stl"/>
      </geometry>
      <material name="BaseLinkColor"/>
    </visual>
    <collision>
      <origin rpy="0 0 0" xyz="0 0 0.0164"/>
      <geometry>
        <cylinder length="0.1651" radius="0.105"/>
      </geometry>
    </collision>
  </link>
  <!-- BASE_LINK_INERTIAL (WORKAROUND FOR KDL WHICH DOES NOT ACCEPT BASE_LINK WITH INERTIA) -->
  <link name="base_link_inertial">
    <inertial>
      <origin rpy="0 0 0" xyz="0 0 0"/>
      <mass value="2.0"/>
      <inertia ixx="0.010055501666666666" ixy="0" ixz="0" iyy="0.010055501666666666" iyz="0" izz="0.011024999999999998"/>
    </inertial>
  </link>
  <!-- BASE_FOOTPRINT -->
  <link name="base_footprint"/>
  <!-- LD06 LASER_LINK -->
  <link name="laser_link">
    <inertial>
      <origin rpy="0 0 0" xyz="0 0 0"/>
      <mass value="0.12"/>
      <inertia ixx="2.5406100000000004e-05" ixy="0" ixz="0" iyy="2.533e-05" iyz="0" izz="2.533e-05"/>
    </inertial>
    <visual>
      <origin rpy="0 0 -1.5707963" xyz="0 0 0"/>
      <geometry>
        <mesh filename="ld06.stl"/>
      </geometry>
      <material name="LaserColor"/>
    </visual>
    <collision>
      <origin rpy="0 0 -1.5707963" xyz="0 0 0.0165"/>
      <geometry>
        <box size="0.038 0.0381 0.033"/>
      </geometry>
    </collision>
  </link>
  <!-- LASER_FRAME -->
  <link name="laser_frame"/>
  <!-- MPU9250 IMU_LINK -->
  <link name="imu_link"/>
  <!-- WHEEL FRONT -->
  <link name="wheel_f">
    <inertial>
      <mass value="0.075"/>
      <inertia ixx="1.999375e-05" ixy="0" ixz="0" iyy="1.999375e-05" iyz="0" izz="3.15375e-05"/>
    </inertial>
    <visual>
      <origin rpy="0 0 0" xyz="0 0 0"/>
      <geometry>
        <mesh filename="omniwheel.stl"/>
      </geometry>
      <material name="WheelsNavColor"/>
    </visual>
    <collision>
      <origin rpy="0 1.5707963 0" xyz="0.013 0 0"/>
      <geometry>
        <cylinder length="0.026" radius="0.029"/>
      </geometry>
    </collision>
  </link>
  <!-- WHEEL LEFT -->
  <link name="wheel_l">
    <inertial>
      <mass value="0.075"/>
      <inertia ixx="1.999375e-05" ixy="0" ixz="0" iyy="1.999375e-05" iyz="0" izz="3.15375e-05"/>
    </inertial>
    <visual>
      <origin rpy="0 0 0" xyz="0 0 0"/>
      <geometry>
        <mesh filename="omniwheel.stl"/>
      </geometry>
      <material name="WheelsNavColor"/>
    </visual>
    <collision>
      <origin rpy="0 1.5707963 0" xyz="0.013 0 0"/>
      <geometry>
        <cylinder length="0.026" radius="0.029"/>
      </geometry>
    </collision>
  </link>
  <!-- WHEEL RIGHT -->
  <link name="wheel_r">
    <inertial>
      <mass value="0.075"/>
      <inertia ixx="1.999375e-05" ixy="0" ixz="0" iyy="1.999375e-05" iyz="0" izz="3.15375e-05"/>
    </inertial>
    <visual>
      <origin rpy="0 0 0" xyz="0 0 0"/>
      <geometry>
        <mesh filename="omniwheel.stl"/>
      </geometry>
      <material name="WheelsNavColor"/>
    </visual>
    <collision>
      <origin rpy="0 1.5707963 0" xyz="0.013 0 0"/>
      <geometry>
        <cylinder length="0.026" radius="0.029"/>
      </geometry>
    </collision>
  </link>
  <!-- **** JOINTS **** -->
  <!-- BASE_FOOTPRINT TO BASE_LINK -->
  <!-- BASE_LINK_INERTIAL TO BASE_LINK -->
  <joint name="base_inertial_fixed" type="fixed">
    <parent link="base_link"/>
    <child link="base_link_inertial"/>
    <origin xyz="0 0 0"/>
  </joint>
  <joint name="base_footprint_fixed" type="fixed">
    <parent link="base_link"/>
    <child link="base_footprint"/>
    <origin xyz="0 0 -0.085597"/>
  </joint>
  <!-- LASER_LINK TO BASE_LINK -->
  <joint name="base_laser_fixed" type="fixed">
    <parent link="base_link"/>
    <child link="laser_link"/>
    <origin xyz="0.034435 0 0.076503"/>
  </joint>
  <!-- LASER_FRAME TO LASER_LINK -->
  <joint name="laser_frame_fixed" type="fixed">
    <parent link="laser_link"/>
    <child link="laser_frame"/>
    <origin xyz="0 0 0.0255"/>
  </joint>
  <!-- IMU_LINK TO BASE_LINK -->
  <joint name="imu_base_fixed" type="fixed">
    <parent link="base_link"/>
    <child link="imu_link"/>
    <origin xyz="0 0 0.063003"/>
  </joint>
  <!-- WHEEL_F TO BASE_LINK -->
  <joint name="joint_f" type="continuous">
    <parent link="base_link"/>
    <child link="wheel_f"/>
    <origin rpy="0 0 0" xyz="0.10683 0 -0.056597"/>
    <axis xyz="1 0 0"/>
  </joint>
  <!-- WHEEL_L TO BASE_LINK -->
  <joint name="joint_l" type="continuous">
    <parent link="base_link"/>
    <child link="wheel_l"/>
    <origin rpy="0 0 2.094395" xyz="-0.053415 0.092518 -0.056597"/>
    <axis xyz="1 0 0"/>
  </joint>
  <!-- WHEEL_R TO BASE_LINK -->
  <joint name="joint_r" type="continuous">
    <parent link="base_link"/>
    <child link="wheel_r"/>
    <origin rpy="0 0 -2.094395" xyz="-0.053415 -0.092518 -0.056597"/>
    <axis xyz="1 0 0"/>
  </joint>
</robot>
